WARNING | 2023-07-17 16:37:01,873 | main.py:46 | BOT WAS STARTED
ERROR | 2023-07-17 18:49:17,681 | dispatcher.py:390 | Cause exception while getting updates.
Traceback (most recent call last):
  File "/Library/Frameworks/Python.framework/Versions/3.9/lib/python3.9/site-packages/aiogram/dispatcher/dispatcher.py", line 381, in start_polling
    updates = await self.bot.get_updates(
  File "/Library/Frameworks/Python.framework/Versions/3.9/lib/python3.9/site-packages/aiogram/bot/bot.py", line 110, in get_updates
    result = await self.request(api.Methods.GET_UPDATES, payload)
  File "/Library/Frameworks/Python.framework/Versions/3.9/lib/python3.9/site-packages/aiogram/bot/base.py", line 236, in request
    return await api.make_request(await self.get_session(), self.server, self.__token, method, data, files,
  File "/Library/Frameworks/Python.framework/Versions/3.9/lib/python3.9/site-packages/aiogram/bot/api.py", line 139, in make_request
    async with session.post(url, data=req, **kwargs) as response:
  File "/Library/Frameworks/Python.framework/Versions/3.9/lib/python3.9/site-packages/aiohttp/client.py", line 1138, in __aenter__
    self._resp = await self._coro
  File "/Library/Frameworks/Python.framework/Versions/3.9/lib/python3.9/site-packages/aiohttp/client.py", line 559, in _request
    await resp.start(conn)
  File "/Library/Frameworks/Python.framework/Versions/3.9/lib/python3.9/site-packages/aiohttp/client_reqrep.py", line 913, in start
    self._continue = None
  File "/Library/Frameworks/Python.framework/Versions/3.9/lib/python3.9/site-packages/aiohttp/helpers.py", line 721, in __exit__
    raise asyncio.TimeoutError from None
asyncio.exceptions.TimeoutError
ERROR | 2023-07-17 20:26:28,564 | dispatcher.py:390 | Cause exception while getting updates.
Traceback (most recent call last):
  File "/Library/Frameworks/Python.framework/Versions/3.9/lib/python3.9/site-packages/aiogram/dispatcher/dispatcher.py", line 381, in start_polling
    updates = await self.bot.get_updates(
  File "/Library/Frameworks/Python.framework/Versions/3.9/lib/python3.9/site-packages/aiogram/bot/bot.py", line 110, in get_updates
    result = await self.request(api.Methods.GET_UPDATES, payload)
  File "/Library/Frameworks/Python.framework/Versions/3.9/lib/python3.9/site-packages/aiogram/bot/base.py", line 236, in request
    return await api.make_request(await self.get_session(), self.server, self.__token, method, data, files,
  File "/Library/Frameworks/Python.framework/Versions/3.9/lib/python3.9/site-packages/aiogram/bot/api.py", line 139, in make_request
    async with session.post(url, data=req, **kwargs) as response:
  File "/Library/Frameworks/Python.framework/Versions/3.9/lib/python3.9/site-packages/aiohttp/client.py", line 1138, in __aenter__
    self._resp = await self._coro
  File "/Library/Frameworks/Python.framework/Versions/3.9/lib/python3.9/site-packages/aiohttp/client.py", line 559, in _request
    await resp.start(conn)
  File "/Library/Frameworks/Python.framework/Versions/3.9/lib/python3.9/site-packages/aiohttp/client_reqrep.py", line 913, in start
    self._continue = None
  File "/Library/Frameworks/Python.framework/Versions/3.9/lib/python3.9/site-packages/aiohttp/helpers.py", line 721, in __exit__
    raise asyncio.TimeoutError from None
asyncio.exceptions.TimeoutError
ERROR | 2023-07-17 23:28:27,395 | dispatcher.py:390 | Cause exception while getting updates.
Traceback (most recent call last):
  File "/Library/Frameworks/Python.framework/Versions/3.9/lib/python3.9/site-packages/aiogram/dispatcher/dispatcher.py", line 381, in start_polling
    updates = await self.bot.get_updates(
  File "/Library/Frameworks/Python.framework/Versions/3.9/lib/python3.9/site-packages/aiogram/bot/bot.py", line 110, in get_updates
    result = await self.request(api.Methods.GET_UPDATES, payload)
  File "/Library/Frameworks/Python.framework/Versions/3.9/lib/python3.9/site-packages/aiogram/bot/base.py", line 236, in request
    return await api.make_request(await self.get_session(), self.server, self.__token, method, data, files,
  File "/Library/Frameworks/Python.framework/Versions/3.9/lib/python3.9/site-packages/aiogram/bot/api.py", line 139, in make_request
    async with session.post(url, data=req, **kwargs) as response:
  File "/Library/Frameworks/Python.framework/Versions/3.9/lib/python3.9/site-packages/aiohttp/client.py", line 1138, in __aenter__
    self._resp = await self._coro
  File "/Library/Frameworks/Python.framework/Versions/3.9/lib/python3.9/site-packages/aiohttp/client.py", line 559, in _request
    await resp.start(conn)
  File "/Library/Frameworks/Python.framework/Versions/3.9/lib/python3.9/site-packages/aiohttp/client_reqrep.py", line 913, in start
    self._continue = None
  File "/Library/Frameworks/Python.framework/Versions/3.9/lib/python3.9/site-packages/aiohttp/helpers.py", line 721, in __exit__
    raise asyncio.TimeoutError from None
asyncio.exceptions.TimeoutError
